<?xml version="1.0" ?>
<robot name="hexa_x_tilt">
  <joint name="hexa_x_tilt__cgo3_mount_joint" type="fixed">
    <parent link="hexa_x_tilt__base_link"/>
    <child link="hexa_x_tilt__cgo3_mount_link"/>
    <origin rpy="0       0      -3.14159" xyz="0   0   0.26"/>
    <axis xyz="0 0 1"/>
    <limit effort="100.0" lower="0.0" upper="0.0" velocity="-1.0"/>
  </joint>
  <joint name="hexa_x_tilt__cgo3_vertical_arm_joint" type="revolute">
    <parent link="hexa_x_tilt__cgo3_mount_link"/>
    <child link="hexa_x_tilt__cgo3_vertical_arm_link"/>
    <origin rpy="0 0 0" xyz="-0.026  0    -0.1"/>
    <axis xyz="0 0 1"/>
    <limit effort="100.0" lower="-1e+16" upper="1e+16" velocity="-1.0"/>
  </joint>
  <joint name="hexa_x_tilt__cgo3_horizontal_arm_joint" type="revolute">
    <parent link="hexa_x_tilt__cgo3_vertical_arm_link"/>
    <child link="hexa_x_tilt__cgo3_horizontal_arm_link"/>
    <origin rpy="0 0 0" xyz="0.052  0    -0.062"/>
    <axis xyz="-1  0  0"/>
    <limit effort="100.0" lower="-0.785398" upper="0.785398" velocity="-1.0"/>
  </joint>
  <joint name="hexa_x_tilt__left_leg_joint" type="revolute">
    <parent link="hexa_x_tilt__base_link"/>
    <child link="hexa_x_tilt__left_leg"/>
    <origin rpy="0       0      -3.14159" xyz="-0.00025  0.04051  0.212"/>
    <axis xyz="-1  0  0"/>
    <limit effort="100.0" lower="0.0" upper="1.0" velocity="-1.0"/>
  </joint>
  <joint name="hexa_x_tilt__right_leg_joint" type="revolute">
    <parent link="hexa_x_tilt__base_link"/>
    <child link="hexa_x_tilt__right_leg"/>
    <origin rpy="0       0      -3.14159" xyz="-0.00025 -0.04051  0.212"/>
    <axis xyz="1 0 0"/>
    <limit effort="100.0" lower="0.0" upper="1.0" velocity="-1.0"/>
  </joint>
  <joint name="hexa_x_tilt__hexa_x_tilt/imu_joint" type="fixed">
    <parent link="hexa_x_tilt__base_link"/>
    <child link="hexa_x_tilt__hexa_x_tilt/imu_link"/>
    <origin rpy="0 0 0" xyz="0   0   0.26"/>
    <axis xyz="-1  0  0"/>
    <limit effort="0.0" lower="0.0" upper="0.0" velocity="0.0"/>
  </joint>
  <joint name="hexa_x_tilt__rotor_3_joint" type="revolute">
    <parent link="hexa_x_tilt__base_link"/>
    <child link="hexa_x_tilt__rotor_3"/>
    <origin rpy="0      0.52    2.10159" xyz="-0.21139 -0.11976  0.34221"/>
    <axis xyz="-2.0e-04 -1.9e-04  1.0e+00"/>
    <limit effort="10.0" lower="-1e+16" upper="1e+16" velocity="-1.0"/>
  </joint>
  <joint name="hexa_x_tilt__rotor_0_joint" type="revolute">
    <parent link="hexa_x_tilt__base_link"/>
    <child link="hexa_x_tilt__rotor_0"/>
    <origin rpy="0       0.52    -2.10159" xyz="0.20939 -0.12276  0.34221"/>
    <axis xyz="-0.00319 -0.00302  0.99999"/>
    <limit effort="10.0" lower="-1e+16" upper="1e+16" velocity="-1.0"/>
  </joint>
  <joint name="hexa_x_tilt__rotor_4_joint" type="revolute">
    <parent link="hexa_x_tilt__base_link"/>
    <child link="hexa_x_tilt__rotor_4"/>
    <origin rpy="0      -0.52    -3.14159" xyz="0.00187 -0.2427   0.34221"/>
    <axis xyz="-0.00311  0       0.99999"/>
    <limit effort="10.0" lower="-1e+16" upper="1e+16" velocity="-1.0"/>
  </joint>
  <joint name="hexa_x_tilt__rotor_1_joint" type="revolute">
    <parent link="hexa_x_tilt__base_link"/>
    <child link="hexa_x_tilt__rotor_1"/>
    <origin rpy="0      -0.52     1.04719" xyz="-0.21139  0.11976  0.34221"/>
    <axis xyz="2.1000e-04 3.3700e-03 9.9999e-01"/>
    <limit effort="10.0" lower="-1e+16" upper="1e+16" velocity="-1.0"/>
  </joint>
  <joint name="hexa_x_tilt__rotor_5_joint" type="revolute">
    <parent link="hexa_x_tilt__base_link"/>
    <child link="hexa_x_tilt__rotor_5"/>
    <origin rpy="0.0e+00 5.2e-01 9.0e-05" xyz="0.00187 0.2427  0.34221"/>
    <axis xyz="3.1100e-03 -4.0000e-05  9.9999e-01"/>
    <limit effort="10.0" lower="-1e+16" upper="1e+16" velocity="-1.0"/>
  </joint>
  <joint name="hexa_x_tilt__rotor_2_joint" type="revolute">
    <parent link="hexa_x_tilt__base_link"/>
    <child link="hexa_x_tilt__rotor_2"/>
    <origin rpy="0      -0.52    -1.04719" xyz="0.20939 0.12276 0.34221"/>
    <axis xyz="0.00322 -0.00657  0.99997"/>
    <limit effort="10.0" lower="-1e+16" upper="1e+16" velocity="-1.0"/>
  </joint>
  <link name="hexa_x_tilt__base_link">
    <inertial>
      <mass value="2.02"/>
      <origin rpy="0 0 0" xyz="0.001  0    -0.009"/>
      <inertia ixx="0.011" ixy="0" ixz="0" iyy="0.015" iyz="0" izz="0.021"/>
    </inertial>
    <collision name="hexa_x_tilt__base_link_collision">
      <origin rpy="0       0      -3.14159" xyz="0   0   0.26"/>
      <geometry>
        <box size="0.67 0.67 0.15"/>
      </geometry>
    </collision>
    <visual name="hexa_x_tilt__base_link_visual">
      <origin rpy="0       0      -3.14159" xyz="0   0   0.26"/>
      <geometry>
        <mesh filename="package://Firmware/sitl_gazebo_fully_actuated/models/hexa_x_tilt/meshes/main_body_remeshed_v3.stl OR Firmware/Tools/sitl_gazebo/models/hexa_x_tilt/meshes/main_body_remeshed_v3.stl OR Firmware/Tools/sitl_gazebo/models/typhoon_h480/meshes/main_body_remeshed_v3.stl" scale="0.001 0.001 0.001"/>
      </geometry>
    </visual>
  </link>
  <link name="hexa_x_tilt__cgo3_mount_link">
    <inertial>
      <mass value="0.1"/>
      <origin rpy="0 0 0" xyz="-0.041  0    -0.162"/>
      <inertia ixx="0.001" ixy="0" ixz="0" iyy="0.001" iyz="0" izz="0.001"/>
    </inertial>
    <visual name="hexa_x_tilt__cgo3_mount_visual">
      <origin rpy="0 0 0" xyz="0 0 0"/>
      <geometry>
        <mesh filename="package://Firmware/sitl_gazebo_fully_actuated/models/hexa_x_tilt/meshes/cgo3_mount_remeshed_v1.stl OR Firmware/Tools/sitl_gazebo/models/hexa_x_tilt/meshes/cgo3_mount_remeshed_v1.stl OR Firmware/Tools/sitl_gazebo/models/typhoon_h480/meshes/cgo3_mount_remeshed_v1.stl" scale="0.001 0.001 0.001"/>
      </geometry>
    </visual>
  </link>
  <link name="hexa_x_tilt__cgo3_vertical_arm_link">
    <inertial>
      <mass value="0.1"/>
      <origin rpy="0 0 0" xyz="-0.041  0    -0.162"/>
      <inertia ixx="0.001" ixy="0" ixz="0" iyy="0.001" iyz="0" izz="0.001"/>
    </inertial>
    <visual name="hexa_x_tilt__cgo3_vertical_arm_visual">
      <origin rpy="0 0 0" xyz="0.026 0    0.1"/>
      <geometry>
        <mesh filename="package://Firmware/sitl_gazebo_fully_actuated/models/hexa_x_tilt/meshes/cgo3_vertical_arm_remeshed_v1.stl OR Firmware/Tools/sitl_gazebo/models/hexa_x_tilt/meshes/cgo3_vertical_arm_remeshed_v1.stl OR Firmware/Tools/sitl_gazebo/models/typhoon_h480/meshes/cgo3_vertical_arm_remeshed_v1.stl" scale="0.001 0.001 0.001"/>
      </geometry>
    </visual>
  </link>
  <link name="hexa_x_tilt__cgo3_horizontal_arm_link">
    <inertial>
      <mass value="0.1"/>
      <origin rpy="0 0 0" xyz="-0.041  0    -0.081"/>
      <inertia ixx="0.001" ixy="0" ixz="0" iyy="0.001" iyz="0" izz="0.001"/>
    </inertial>
    <visual name="hexa_x_tilt__cgo3_horizontal_arm_visual">
      <origin rpy="0 0 0" xyz="-0.026  0     0.162"/>
      <geometry>
        <mesh filename="package://Firmware/sitl_gazebo_fully_actuated/models/hexa_x_tilt/meshes/cgo3_horizontal_arm_remeshed_v1.stl OR Firmware/Tools/sitl_gazebo/models/hexa_x_tilt/meshes/cgo3_horizontal_arm_remeshed_v1.stl OR Firmware/Tools/sitl_gazebo/models/typhoon_h480/meshes/cgo3_horizontal_arm_remeshed_v1.stl" scale="0.001 0.001 0.001"/>
      </geometry>
    </visual>
  </link>
  <link name="hexa_x_tilt__left_leg">
    <inertial>
      <mass value="0.1"/>
      <origin rpy="0 0 0" xyz="0      -0.14313 -0.20725"/>
      <inertia ixx="0.001" ixy="0" ixz="0" iyy="0.001" iyz="0" izz="0.001"/>
    </inertial>
    <collision name="hexa_x_tilt__collision">
      <origin rpy="0      1.56893 0" xyz="-0.00526 -0.10262 -0.15925"/>
      <geometry>
        <cylinder length="0.3" radius="0.012209"/>
      </geometry>
    </collision>
    <collision name="hexa_x_tilt__collision_bar">
      <origin rpy="-0.50131  0       0" xyz="0.00025 -0.04451 -0.07318"/>
      <geometry>
        <cylinder length="0.176893" radius="0.00914984"/>
      </geometry>
    </collision>
    <visual name="hexa_x_tilt__base_link_left_leg">
      <origin rpy="0 0 0" xyz="-0.00025  0.04051  0.048"/>
      <geometry>
        <mesh filename="package://Firmware/sitl_gazebo_fully_actuated/models/hexa_x_tilt/meshes/leg2_remeshed_v3.stl OR Firmware/Tools/sitl_gazebo/models/hexa_x_tilt/meshes/leg2_remeshed_v3.stl OR Firmware/Tools/sitl_gazebo/models/typhoon_h480/meshes/leg2_remeshed_v3.stl" scale="0.001 0.001 0.001"/>
      </geometry>
    </visual>
  </link>
  <link name="hexa_x_tilt__right_leg">
    <inertial>
      <mass value="0.1"/>
      <origin rpy="0 0 0" xyz="0       0.14313 -0.20725"/>
      <inertia ixx="0.001" ixy="0" ixz="0" iyy="0.001" iyz="0" izz="0.001"/>
    </inertial>
    <collision name="hexa_x_tilt__collision">
      <origin rpy="0      1.56893 0" xyz="-0.00526  0.10262 -0.15925"/>
      <geometry>
        <cylinder length="0.3" radius="0.012209"/>
      </geometry>
    </collision>
    <collision name="hexa_x_tilt__collision_bar">
      <origin rpy="0.50131 0      0" xyz="0.00025  0.04451 -0.07318"/>
      <geometry>
        <cylinder length="0.176893" radius="0.00914984"/>
      </geometry>
    </collision>
    <visual name="hexa_x_tilt__base_link_right_leg">
      <origin rpy="0 0 0" xyz="-0.00025 -0.04051  0.048"/>
      <geometry>
        <mesh filename="package://Firmware/sitl_gazebo_fully_actuated/models/hexa_x_tilt/meshes/leg1_remeshed_v3.stl OR Firmware/Tools/sitl_gazebo/models/hexa_x_tilt/meshes/leg1_remeshed_v3.stl OR Firmware/Tools/sitl_gazebo/models/typhoon_h480/meshes/leg1_remeshed_v3.stl" scale="0.001 0.001 0.001"/>
      </geometry>
    </visual>
  </link>
  <link name="hexa_x_tilt__hexa_x_tilt/imu_link">
    <inertial>
      <mass value="0.015"/>
      <origin rpy="0 0 0" xyz="0 0 0"/>
      <inertia ixx="1e-05" ixy="0" ixz="0" iyy="1e-05" iyz="0" izz="1e-05"/>
    </inertial>
  </link>
  <link name="hexa_x_tilt__rotor_3">
    <inertial>
      <mass value="0.005"/>
      <origin rpy="0 0 0" xyz="0 0 0"/>
      <inertia ixx="9.75e-07" ixy="0" ixz="0" iyy="0.000273104" iyz="0" izz="0.000274004"/>
    </inertial>
    <visual name="hexa_x_tilt__rotor_3_visual">
      <origin rpy="0 0 0" xyz="-0.21139 -0.11976 -0.08221"/>
      <geometry>
        <mesh filename="package://Firmware/sitl_gazebo_fully_actuated/models/hexa_x_tilt/meshes/prop_ccw_assembly_remeshed_v3.stl OR Firmware/Tools/sitl_gazebo/models/hexa_x_tilt/meshes/prop_ccw_assembly_remeshed_v3.stl OR Firmware/Tools/sitl_gazebo/models/typhoon_h480/meshes/prop_ccw_assembly_remeshed_v3.stl" scale="0.001 0.001 0.001"/>
      </geometry>
    </visual>
  </link>
  <link name="hexa_x_tilt__rotor_0">
    <inertial>
      <mass value="0.005"/>
      <origin rpy="0 0 0" xyz="0 0 0"/>
      <inertia ixx="9.75e-07" ixy="0" ixz="0" iyy="0.000273104" iyz="0" izz="0.000274004"/>
    </inertial>
    <visual name="hexa_x_tilt__rotor_0_visual">
      <origin rpy="0 0 0" xyz="-0.21139 -0.11976 -0.08221"/>
      <geometry>
        <mesh filename="package://Firmware/sitl_gazebo_fully_actuated/models/hexa_x_tilt/meshes/prop_ccw_assembly_remeshed_v3.stl OR Firmware/Tools/sitl_gazebo/models/hexa_x_tilt/meshes/prop_ccw_assembly_remeshed_v3.stl OR Firmware/Tools/sitl_gazebo/models/typhoon_h480/meshes/prop_ccw_assembly_remeshed_v3.stl" scale="0.001 0.001 0.001"/>
      </geometry>
    </visual>
  </link>
  <link name="hexa_x_tilt__rotor_4">
    <inertial>
      <mass value="0.005"/>
      <origin rpy="0 0 0" xyz="0 0 0"/>
      <inertia ixx="9.75e-07" ixy="0" ixz="0" iyy="0.000273104" iyz="0" izz="0.000274004"/>
    </inertial>
    <collision name="hexa_x_tilt__rotor_4_collision">
      <origin rpy="0 0 0" xyz="0 0 0"/>
      <geometry>
        <cylinder length="0.005" radius="0.128"/>
      </geometry>
    </collision>
    <visual name="hexa_x_tilt__rotor_4_visual">
      <origin rpy="0 0 0" xyz="0.00187 -0.2427  -0.08221"/>
      <geometry>
        <mesh filename="package://Firmware/sitl_gazebo_fully_actuated/models/hexa_x_tilt/meshes/prop_cw_assembly_remeshed_v3.stl OR Firmware/Tools/sitl_gazebo/models/hexa_x_tilt/meshes/prop_cw_assembly_remeshed_v3.stl OR Firmware/Tools/sitl_gazebo/models/typhoon_h480/meshes/prop_cw_assembly_remeshed_v3.stl" scale="0.001 0.001 0.001"/>
      </geometry>
    </visual>
  </link>
  <link name="hexa_x_tilt__rotor_1">
    <inertial>
      <mass value="0.005"/>
      <origin rpy="0 0 0" xyz="0 0 0"/>
      <inertia ixx="9.75e-07" ixy="0" ixz="0" iyy="0.000273104" iyz="0" izz="0.000274004"/>
    </inertial>
    <collision name="hexa_x_tilt__rotor_1_collision">
      <origin rpy="0 0 0" xyz="0 0 0"/>
      <geometry>
        <cylinder length="0.005" radius="0.128"/>
      </geometry>
    </collision>
    <visual name="hexa_x_tilt__rotor_1_visual">
      <origin rpy="0 0 0" xyz="0.00187 -0.2427  -0.08221"/>
      <geometry>
        <mesh filename="package://Firmware/sitl_gazebo_fully_actuated/models/hexa_x_tilt/meshes/prop_cw_assembly_remeshed_v3.stl OR Firmware/Tools/sitl_gazebo/models/hexa_x_tilt/meshes/prop_cw_assembly_remeshed_v3.stl OR Firmware/Tools/sitl_gazebo/models/typhoon_h480/meshes/prop_cw_assembly_remeshed_v3.stl" scale="0.001 0.001 0.001"/>
      </geometry>
    </visual>
  </link>
  <link name="hexa_x_tilt__rotor_5">
    <inertial>
      <mass value="0.005"/>
      <origin rpy="0 0 0" xyz="0 0 0"/>
      <inertia ixx="9.75e-07" ixy="0" ixz="0" iyy="0.000273104" iyz="0" izz="0.000274004"/>
    </inertial>
    <visual name="hexa_x_tilt__rotor_5_visual">
      <origin rpy="0 0 0" xyz="-0.21139 -0.11976 -0.08221"/>
      <geometry>
        <mesh filename="package://Firmware/sitl_gazebo_fully_actuated/models/hexa_x_tilt/meshes/prop_ccw_assembly_remeshed_v3.stl OR Firmware/Tools/sitl_gazebo/models/hexa_x_tilt/meshes/prop_ccw_assembly_remeshed_v3.stl OR Firmware/Tools/sitl_gazebo/models/typhoon_h480/meshes/prop_ccw_assembly_remeshed_v3.stl" scale="0.001 0.001 0.001"/>
      </geometry>
    </visual>
  </link>
  <link name="hexa_x_tilt__rotor_2">
    <inertial>
      <mass value="0.005"/>
      <origin rpy="0 0 0" xyz="0 0 0"/>
      <inertia ixx="9.75e-07" ixy="0" ixz="0" iyy="0.000273104" iyz="0" izz="0.000274004"/>
    </inertial>
    <collision name="hexa_x_tilt__rotor_2_collision">
      <origin rpy="0 0 0" xyz="0 0 0"/>
      <geometry>
        <cylinder length="0.005" radius="0.128"/>
      </geometry>
    </collision>
    <visual name="hexa_x_tilt__rotor_2_visual">
      <origin rpy="0 0 0" xyz="0.00187 -0.2427  -0.08221"/>
      <geometry>
        <mesh filename="package://Firmware/sitl_gazebo_fully_actuated/models/hexa_x_tilt/meshes/prop_cw_assembly_remeshed_v3.stl OR Firmware/Tools/sitl_gazebo/models/hexa_x_tilt/meshes/prop_cw_assembly_remeshed_v3.stl OR Firmware/Tools/sitl_gazebo/models/typhoon_h480/meshes/prop_cw_assembly_remeshed_v3.stl" scale="0.001 0.001 0.001"/>
      </geometry>
    </visual>
  </link>
    <!-- Ground truth odometry sensor -->
  <gazebo>
    <plugin name="p3d_base_controller" filename="libgazebo_ros_p3d.so">
      <alwaysOn>true</alwaysOn>
      <updateRate>200.0</updateRate>
      <bodyName>base_link</bodyName> <!-- This is the link for which ground truth data will be published. It is also used as the child_frame_id in the odometry message, which is not the correct thing to do because the linear and angular velocity are actually in the world frame, not the 'bodyName' frame. The core_odometry_transform packge will handle this by publishing a new odometry message with the frame_id and child_frame_id corrected.  -->
      <topicName>ground_truth/state</topicName>
      <gaussianNoise>0.0</gaussianNoise>
      <frameName>world</frameName>
      <xyzOffsets>0 0 0</xyzOffsets>
      <rpyOffsets>0 0 0</rpyOffsets>
    </plugin>
  </gazebo>
</robot>
